Workbook
Name _27_Year: #REF!
Name _27_Year: #REF!
Name _27_Year: #REF!
Name Accounting_Method: #REF!
Name Accounting_Method: Definitions!#REF!
Name Building_Use: #REF!
Name Building_Use: Definitions!#REF!
Name Business_Activity_Code: #REF!
Name Business_Activity_Code: #REF!
Name Business_Activity_Code: Definitions!#REF!
Name Construction_Class: #REF!
Name Construction_Class: #REF!
Name Construction_Class: Definitions!#REF!
Name Occupancy_Type: #REF!
Name Occupancy_Type: #REF!
Name Occupancy_Type: Definitions!#REF!
Name Roofing: #REF!
Name Roofing: #REF!
Name Roofing: Definitions!#REF!
Name Siding: #REF!
Name Siding: Definitions!#REF!
Name Trade_Business: #REF!
Name Trade_Business: Definitions!#REF!
Name Year_No.: _275_Year
Name Year_No.: _275_Year
Name Year_No.: _275_Year
Name Year_No.: _275_Year
Name Year_No.: _275_Year
Name Yes_No: #REF!
Name Yes_No: Definitions!#REF!

Sheet Study Data
A1: Study Meta Data
A2: Property Address | B2: ='Client Summary'!G12 -> 861 E 800 S, Salt Lake City, UT 84102
A4: Analysis Date | B4: =DATE(B5,12,31) -> 46022 | D4: Basis (excluding land value) | E4: ='Client Summary'!$G$18 -> 0
A5: Study Tax Year | B5: ='Client Summary'!N13 -> 2025 | D5: ="Accumulated Depreciation as of 12/31/"&$B$5-1 -> Accumulated Depreciation as of 12/31/2024 | E5: ='Client Summary'!G19 -> 0
A6: Date Placed in Service | B6: ='Client Summary'!$G$13 -> 45292 | D6: Building Use | E6: =_xlfn.XLOOKUP('Client Summary'!$G$21,Definitions!$E$2:$E$35,Definitions!$F$2:$F$35,0,0,1) -> Single Family Residence
D9: Post Modeling Calculation | G9: Per Modeling Calculation
A10: Asset ID | B10: Property Description | C10: Date Acquired | D10: Original Basis | E10: Life (years) | F10: Estimate Input | G10: Reclassified Basis | H10: Life | I10: Method | J10: Conv | K10: ="Revised Depreciation for the Year ending 12/31/"&$B$5-1 -> Revised Depreciation for the Year ending 12/31/2024
A11: 1 | B11: Building | C11: =$B$6 -> 45292 | D11: =$E$4 -> 0 | E11: ='Client Summary'!G26 -> 27.5 | F11: =1-SUM(F12:F14) -> 0.8 | G11: =IF('Client Summary'!F26=0,'Study Data'!$D$15*'Study Data'!F11,'Client Summary'!F26) -> 0 | H11: =E11 -> 27.5 | I11: SL | J11: Mid-Month | K11: =IF($E$11=27.5,VLOOKUP($B$5-1,_27.5_Year_Post_CS[[#All],[Year]:[Cumulative Depreciation]],5),VLOOKUP($B$5-1,_39_Year_Post_CS12[[#All],[Year]:[Cumulative Depreciation]],5)) -> 0
A12: 1.1 | B12: Asset Class 57.0 - Distributive Trades and Services | C12: =$B$6 -> 45292 | D12: 0 | E12: 5 | F12: =_xlfn.XLOOKUP('Client Summary'!$G$21,Definitions!$E$2:$E$44,Definitions!$G$2:$G$44,0,0,1) -> 0.12 | G12: =IF('Client Summary'!F27=0,'Study Data'!$D$15*'Study Data'!F12,'Client Summary'!F27) -> 0 | H12: 5 | I12: 200DB | J12: Half-Year | K12: =VLOOKUP($B$5-1,_5_Year_Post_CS[[#All],[Year]:[Cumulative Depreciation]],5) -> 0
A13: 1.2 | B13: Asset Class 0.11 - Office Furniture, Fixtures and Equipment | C13: =$B$6 -> 45292 | D13: 0 | E13: 7 | F13: 0 | G13: =IF('Client Summary'!F28=0,'Study Data'!$D$15*'Study Data'!F13,'Client Summary'!F28) -> 0 | H13: 7 | I13: 200DB | J13: Half-Year | K13: =VLOOKUP($B$5-1,_7_Year_Post_CS[[#All],[Year]:[Cumulative Depreciation]],5) -> 0
A14: 1.3 | B14: Asset Class 0.30 - Land Improvements | C14: =$B$6 -> 45292 | D14: 0 | E14: 15 | F14: =_xlfn.XLOOKUP('Client Summary'!$G$21,Definitions!$E$2:$E$44,Definitions!$H$2:$H$44,0,0,1) -> 0.08 | G14: =IF('Client Summary'!F29=0,'Study Data'!$D$15*'Study Data'!F14,'Client Summary'!F29) -> 0 | H14: 15 | I14: 150DB | J14: Half-Year | K14: =VLOOKUP($B$5-1,_15_Year_Post_CS[[#All],[Year]:[Cumulative Depreciation]],5) -> 0
B15: TOTALS | D15: =SUM(D11:D14) -> 0 | F15: =SUM(F11:F14) -> 1 | G15: =SUM(G11:G14) -> 0 | K15: =SUM(K11:K14) -> 0
A18: Building (Pre CS Study) | H18: Building (Post CS Study) | O18: Personal Property (5 Year) | V18: Personal Property (7 Year) | AC18: Land Improvements (15 Year)
A19: 27.5 Yr SL | H19: 27.5 Yr SL | O19: 5 Yr 200 DB | S19: Convention | T19: =J12 -> Half-Year | V19: 7 Yr 200 DB | Z19: Convention | AA19: =J13 -> Half-Year | AC19: 15 Yr 150 DB | AG19: Convention | AH19: =J14 -> Half-Year
A20: Year No. | B20: Year | C20: 27.5-Year Rate | D20: Original Basis | E20: Annual Depreciation | F20: Cumulative Depreciation | H20: Year No. | I20: Year | J20: 27.5-Year Rate | K20: Adj Basis | L20: Annual Depreciation | M20: Cumulative Depreciation | O20: Year No. | P20: Year | Q20: 5-Year Rate | R20: Basis | S20: Annual Depreciation | T20: Cumulative Depreciation | V20: Year No. | W20: Year | X20: 7-Year Rate | Y20: Basis | Z20: Annual Depreciation | AA20: Cumulative Depreciation | AC20: Year No. | AD20: Year | AE20: 15-Year Rate | AF20: Basis | AG20: Annual Depreciation | AH20: Cumulative Depreciation
A21: 1 | B21: =IF($B$6>0,YEAR($B$6),"") -> 2024 | C21: {=INDEX('27.5-Year'!$A$1:$M$32,MATCH(_27.5_Year_Original[[#This Row],[Year No.]],'27.5-Year'!$A:$A,0),MONTH('Study Data'!$B$6)+1)} -> 0.03485 | D21: =IF($E$11=27.5,$D$11,0) -> 0 | E21: =_27.5_Year_Original[[#This Row],[Original Basis]]*_27.5_Year_Original[[#This Row],[27.5-Year Rate]] -> 0 | F21: =E21 -> 0 | H21: 1 | I21: =IF($B$6>0,YEAR($B$6),"") -> 2024 | J21: {=INDEX('27.5-Year'!$A$1:$M$32,MATCH(_27.5_Year_Post_CS[[#This Row],[Year No.]],'27.5-Year'!$A:$A,0),MONTH('Study Data'!$B$6)+1)} -> 0.03485 | K21: =IF($E$11=27.5,$G$11,0) -> 0 | L21: =_27.5_Year_Post_CS[[#This Row],[Adj Basis]]*_27.5_Year_Post_CS[[#This Row],[27.5-Year Rate]] -> 0 | M21: =L21 -> 0 | O21: 1 | P21: =IF($B$6>0,YEAR($B$6),"") -> 2024 | Q21: 0.2 | R21: =$G$12-$Q$28 -> 0 | S21: =_5_Year_Post_CS[[#This Row],[Basis]]*_5_Year_Post_CS[[#This Row],[5-Year Rate]] -> 0 | T21: =S21+Q28 -> 0 | V21: 1 | W21: =IF($B$6>0,YEAR($B$6),"") -> 2024 | X21: 0.1429 | Y21: =$G$13-$X$30 -> 0 | Z21: =_7_Year_Post_CS[[#This Row],[Basis]]*_7_Year_Post_CS[[#This Row],[7-Year Rate]] -> 0 | AA21: =Z21+X30 -> 0 | AC21: 1 | AD21: =IF($B$6>0,YEAR($B$6),"") -> 2024 | AE21: 0.05 | AF21: =$G$14-$AE$38 -> 0 | AG21: =_15_Year_Post_CS[[#This Row],[Basis]]*_15_Year_Post_CS[[#This Row],[15-Year Rate]] -> 0 | AH21: =AG21+AE38 -> 0
A22: =A21+1 -> 2 | B22: =B21+1 -> 2025 | C22: {=INDEX('27.5-Year'!$A$1:$M$32,MATCH(_27.5_Year_Original[[#This Row],[Year No.]],'27.5-Year'!$A:$A,0),MONTH('Study Data'!$B$6)+1)} -> 0.03636 | D22: =IF($E$11=27.5,$D$11,0) -> 0 | E22: =_27.5_Year_Original[[#This Row],[Original Basis]]*_27.5_Year_Original[[#This Row],[27.5-Year Rate]] -> 0 | F22: =F21+_27.5_Year_Original[[#This Row],[Annual Depreciation]] -> 0 | H22: =H21+1 -> 2 | I22: =I21+1 -> 2025 | J22: {=INDEX('27.5-Year'!$A$1:$M$32,MATCH(_27.5_Year_Post_CS[[#This Row],[Year No.]],'27.5-Year'!$A:$A,0),MONTH('Study Data'!$B$6)+1)} -> 0.03636 | K22: =IF($E$11=27.5,$G$11,0) -> 0 | L22: =_27.5_Year_Post_CS[[#This Row],[Adj Basis]]*_27.5_Year_Post_CS[[#This Row],[27.5-Year Rate]] -> 0 | M22: =M21+_27.5_Year_Post_CS[[#This Row],[Annual Depreciation]] -> 0 | O22: =O21+1 -> 2 | P22: =P21+1 -> 2025 | Q22: 0.32 | R22: =$G$12-$Q$28 -> 0 | S22: =_5_Year_Post_CS[[#This Row],[Basis]]*_5_Year_Post_CS[[#This Row],[5-Year Rate]] -> 0 | T22: =T21+_5_Year_Post_CS[[#This Row],[Annual Depreciation]] -> 0 | V22: =V21+1 -> 2 | W22: =W21+1 -> 2025 | X22: 0.2449 | Y22: =$G$13-$X$30 -> 0 | Z22: =_7_Year_Post_CS[[#This Row],[Basis]]*_7_Year_Post_CS[[#This Row],[7-Year Rate]] -> 0 | AA22: =AA21+_7_Year_Post_CS[[#This Row],[Annual Depreciation]] -> 0 | AC22: =AC21+1 -> 2 | AD22: =AD21+1 -> 2025 | AE22: 0.095 | AF22: =$G$14-$AE$38 -> 0 | AG22: =_15_Year_Post_CS[[#This Row],[Basis]]*_15_Year_Post_CS[[#This Row],[15-Year Rate]] -> 0 | AH22: =AH21+_15_Year_Post_CS[[#This Row],[Annual Depreciation]] -> 0
A23: =A22+1 -> 3 | B23: =B22+1 -> 2026 | C23: {=INDEX('27.5-Year'!$A$1:$M$32,MATCH(_27.5_Year_Original[[#This Row],[Year No.]],'27.5-Year'!$A:$A,0),MONTH('Study Data'!$B$6)+1)} -> 0.03636 | D23: =IF($E$11=27.5,$D$11,0) -> 0 | E23: =_27.5_Year_Original[[#This Row],[Original Basis]]*_27.5_Year_Original[[#This Row],[27.5-Year Rate]] -> 0 | F23: =F22+_27.5_Year_Original[[#This Row],[Annual Depreciation]] -> 0 | H23: =H22+1 -> 3 | I23: =I22+1 -> 2026 | J23: {=INDEX('27.5-Year'!$A$1:$M$32,MATCH(_27.5_Year_Post_CS[[#This Row],[Year No.]],'27.5-Year'!$A:$A,0),MONTH('Study Data'!$B$6)+1)} -> 0.03636 | K23: =IF($E$11=27.5,$G$11,0) -> 0 | L23: =_27.5_Year_Post_CS[[#This Row],[Adj Basis]]*_27.5_Year_Post_CS[[#This Row],[27.5-Year Rate]] -> 0 | M23: =M22+_27.5_Year_Post_CS[[#This Row],[Annual Depreciation]] -> 0 | O23: =O22+1 -> 3 | P23: =P22+1 -> 2026 | Q23: 0.192 | R23: =$G$12-$Q$28 -> 0 | S23: =_5_Year_Post_CS[[#This Row],[Basis]]*_5_Year_Post_CS[[#This Row],[5-Year Rate]] -> 0 | T23: =T22+_5_Year_Post_CS[[#This Row],[Annual Depreciation]] -> 0 | V23: =V22+1 -> 3 | W23: =W22+1 -> 2026 | X23: 0.1749 | Y23: =$G$13-$X$30 -> 0 | Z23: =_7_Year_Post_CS[[#This Row],[Basis]]*_7_Year_Post_CS[[#This Row],[7-Year Rate]] -> 0 | AA23: =AA22+_7_Year_Post_CS[[#This Row],[Annual Depreciation]] -> 0 | AC23: =AC22+1 -> 3 | AD23: =AD22+1 -> 2026 | AE23: 0.0855 | AF23: =$G$14-$AE$38 -> 0 | AG23: =_15_Year_Post_CS[[#This Row],[Basis]]*_15_Year_Post_CS[[#This Row],[15-Year Rate]] -> 0 | AH23: =AH22+_15_Year_Post_CS[[#This Row],[Annual Depreciation]] -> 0
A24: =A23+1 -> 4 | B24: =B23+1 -> 2027 | C24: {=INDEX('27.5-Year'!$A$1:$M$32,MATCH(_27.5_Year_Original[[#This Row],[Year No.]],'27.5-Year'!$A:$A,0),MONTH('Study Data'!$B$6)+1)} -> 0.03636 | D24: =IF($E$11=27.5,$D$11,0) -> 0 | E24: =_27.5_Year_Original[[#This Row],[Original Basis]]*_27.5_Year_Original[[#This Row],[27.5-Year Rate]] -> 0 | F24: =F23+_27.5_Year_Original[[#This Row],[Annual Depreciation]] -> 0 | H24: =H23+1 -> 4 | I24: =I23+1 -> 2027 | J24: {=INDEX('27.5-Year'!$A$1:$M$32,MATCH(_27.5_Year_Post_CS[[#This Row],[Year No.]],'27.5-Year'!$A:$A,0),MONTH('Study Data'!$B$6)+1)} -> 0.03636 | K24: =IF($E$11=27.5,$G$11,0) -> 0 | L24: =_27.5_Year_Post_CS[[#This Row],[Adj Basis]]*_27.5_Year_Post_CS[[#This Row],[27.5-Year Rate]] -> 0 | M24: =M23+_27.5_Year_Post_CS[[#This Row],[Annual Depreciation]] -> 0 | O24: =O23+1 -> 4 | P24: =P23+1 -> 2027 | Q24: 0.1152 | R24: =$G$12-$Q$28 -> 0 | S24: =_5_Year_Post_CS[[#This Row],[Basis]]*_5_Year_Post_CS[[#This Row],[5-Year Rate]] -> 0 | T24: =T23+_5_Year_Post_CS[[#This Row],[Annual Depreciation]] -> 0 | V24: =V23+1 -> 4 | W24: =W23+1 -> 2027 | X24: 0.1249 | Y24: =$G$13-$X$30 -> 0 | Z24: =_7_Year_Post_CS[[#This Row],[Basis]]*_7_Year_Post_CS[[#This Row],[7-Year Rate]] -> 0 | AA24: =AA23+_7_Year_Post_CS[[#This Row],[Annual Depreciation]] -> 0 | AC24: =AC23+1 -> 4 | AD24: =AD23+1 -> 2027 | AE24: 0.077 | AF24: =$G$14-$AE$38 -> 0 | AG24: =_15_Year_Post_CS[[#This Row],[Basis]]*_15_Year_Post_CS[[#This Row],[15-Year Rate]] -> 0 | AH24: =AH23+_15_Year_Post_CS[[#This Row],[Annual Depreciation]] -> 0
A25: =A24+1 -> 5 | B25: =B24+1 -> 2028 | C25: {=INDEX('27.5-Year'!$A$1:$M$32,MATCH(_27.5_Year_Original[[#This Row],[Year No.]],'27.5-Year'!$A:$A,0),MONTH('Study Data'!$B$6)+1)} -> 0.03636 | D25: =IF($E$11=27.5,$D$11,0) -> 0 | E25: =_27.5_Year_Original[[#This Row],[Original Basis]]*_27.5_Year_Original[[#This Row],[27.5-Year Rate]] -> 0 | F25: =F24+_27.5_Year_Original[[#This Row],[Annual Depreciation]] -> 0 | H25: =H24+1 -> 5 | I25: =I24+1 -> 2028 | J25: {=INDEX('27.5-Year'!$A$1:$M$32,MATCH(_27.5_Year_Post_CS[[#This Row],[Year No.]],'27.5-Year'!$A:$A,0),MONTH('Study Data'!$B$6)+1)} -> 0.03636 | K25: =IF($E$11=27.5,$G$11,0) -> 0 | L25: =_27.5_Year_Post_CS[[#This Row],[Adj Basis]]*_27.5_Year_Post_CS[[#This Row],[27.5-Year Rate]] -> 0 | M25: =M24+_27.5_Year_Post_CS[[#This Row],[Annual Depreciation]] -> 0 | O25: =O24+1 -> 5 | P25: =P24+1 -> 2028 | Q25: 0.1152 | R25: =$G$12-$Q$28 -> 0 | S25: =_5_Year_Post_CS[[#This Row],[Basis]]*_5_Year_Post_CS[[#This Row],[5-Year Rate]] -> 0 | T25: =T24+_5_Year_Post_CS[[#This Row],[Annual Depreciation]] -> 0 | V25: =V24+1 -> 5 | W25: =W24+1 -> 2028 | X25: 0.0893 | Y25: =$G$13-$X$30 -> 0 | Z25: =_7_Year_Post_CS[[#This Row],[Basis]]*_7_Year_Post_CS[[#This Row],[7-Year Rate]] -> 0 | AA25: =AA24+_7_Year_Post_CS[[#This Row],[Annual Depreciation]] -> 0 | AC25: =AC24+1 -> 5 | AD25: =AD24+1 -> 2028 | AE25: 0.0693 | AF25: =$G$14-$AE$38 -> 0 | AG25: =_15_Year_Post_CS[[#This Row],[Basis]]*_15_Year_Post_CS[[#This Row],[15-Year Rate]] -> 0 | AH25: =AH24+_15_Year_Post_CS[[#This Row],[Annual Depreciation]] -> 0
A26: =A25+1 -> 6 | B26: =B25+1 -> 2029 | C26: {=INDEX('27.5-Year'!$A$1:$M$32,MATCH(_27.5_Year_Original[[#This Row],[Year No.]],'27.5-Year'!$A:$A,0),MONTH('Study Data'!$B$6)+1)} -> 0.03636 | D26: =IF($E$11=27.5,$D$11,0) -> 0 | E26: =_27.5_Year_Original[[#This Row],[Original Basis]]*_27.5_Year_Original[[#This Row],[27.5-Year Rate]] -> 0 | F26: =F25+_27.5_Year_Original[[#This Row],[Annual Depreciation]] -> 0 | H26: =H25+1 -> 6 | I26: =I25+1 -> 2029 | J26: {=INDEX('27.5-Year'!$A$1:$M$32,MATCH(_27.5_Year_Post_CS[[#This Row],[Year No.]],'27.5-Year'!$A:$A,0),MONTH('Study Data'!$B$6)+1)} -> 0.03636 | K26: =IF($E$11=27.5,$G$11,0) -> 0 | L26: =_27.5_Year_Post_CS[[#This Row],[Adj Basis]]*_27.5_Year_Post_CS[[#This Row],[27.5-Year Rate]] -> 0 | M26: =M25+_27.5_Year_Post_CS[[#This Row],[Annual Depreciation]] -> 0 | O26: =O25+1 -> 6 | P26: =P25+1 -> 2029 | Q26: 0.0576 | R26: =$G$12-$Q$28 -> 0 | S26: =_5_Year_Post_CS[[#This Row],[Basis]]*_5_Year_Post_CS[[#This Row],[5-Year Rate]] -> 0 | T26: =T25+_5_Year_Post_CS[[#This Row],[Annual Depreciation]] -> 0 | V26: =V25+1 -> 6 | W26: =W25+1 -> 2029 | X26: 0.0892 | Y26: =$G$13-$X$30 -> 0 | Z26: =_7_Year_Post_CS[[#This Row],[Basis]]*_7_Year_Post_CS[[#This Row],[7-Year Rate]] -> 0 | AA26: =AA25+_7_Year_Post_CS[[#This Row],[Annual Depreciation]] -> 0 | AC26: =AC25+1 -> 6 | AD26: =AD25+1 -> 2029 | AE26: 0.0623 | AF26: =$G$14-$AE$38 -> 0 | AG26: =_15_Year_Post_CS[[#This Row],[Basis]]*_15_Year_Post_CS[[#This Row],[15-Year Rate]] -> 0 | AH26: =AH25+_15_Year_Post_CS[[#This Row],[Annual Depreciation]] -> 0
A27: =A26+1 -> 7 | B27: =B26+1 -> 2030 | C27: {=INDEX('27.5-Year'!$A$1:$M$32,MATCH(_27.5_Year_Original[[#This Row],[Year No.]],'27.5-Year'!$A:$A,0),MONTH('Study Data'!$B$6)+1)} -> 0.03636 | D27: =IF($E$11=27.5,$D$11,0) -> 0 | E27: =_27.5_Year_Original[[#This Row],[Original Basis]]*_27.5_Year_Original[[#This Row],[27.5-Year Rate]] -> 0 | F27: =F26+_27.5_Year_Original[[#This Row],[Annual Depreciation]] -> 0 | H27: =H26+1 -> 7 | I27: =I26+1 -> 2030 | J27: {=INDEX('27.5-Year'!$A$1:$M$32,MATCH(_27.5_Year_Post_CS[[#This Row],[Year No.]],'27.5-Year'!$A:$A,0),MONTH('Study Data'!$B$6)+1)} -> 0.03636 | K27: =IF($E$11=27.5,$G$11,0) -> 0 | L27: =_27.5_Year_Post_CS[[#This Row],[Adj Basis]]*_27.5_Year_Post_CS[[#This Row],[27.5-Year Rate]] -> 0 | M27: =M26+_27.5_Year_Post_CS[[#This Row],[Annual Depreciation]] -> 0 | V27: =V26+1 -> 7 | W27: =W26+1 -> 2030 | X27: 0.0893 | Y27: =$G$13-$X$30 -> 0 | Z27: =_7_Year_Post_CS[[#This Row],[Basis]]*_7_Year_Post_CS[[#This Row],[7-Year Rate]] -> 0 | AA27: =AA26+_7_Year_Post_CS[[#This Row],[Annual Depreciation]] -> 0 | AC27: =AC26+1 -> 7 | AD27: =AD26+1 -> 2030 | AE27: 0.059 | AF27: =$G$14-$AE$38 -> 0 | AG27: =_15_Year_Post_CS[[#This Row],[Basis]]*_15_Year_Post_CS[[#This Row],[15-Year Rate]] -> 0 | AH27: =AH26+_15_Year_Post_CS[[#This Row],[Annual Depreciation]] -> 0
A28: =A27+1 -> 8 | B28: =B27+1 -> 2031 | C28: {=INDEX('27.5-Year'!$A$1:$M$32,MATCH(_27.5_Year_Original[[#This Row],[Year No.]],'27.5-Year'!$A:$A,0),MONTH('Study Data'!$B$6)+1)} -> 0.03636 | D28: =IF($E$11=27.5,$D$11,0) -> 0 | E28: =_27.5_Year_Original[[#This Row],[Original Basis]]*_27.5_Year_Original[[#This Row],[27.5-Year Rate]] -> 0 | F28: =F27+_27.5_Year_Original[[#This Row],[Annual Depreciation]] -> 0 | H28: =H27+1 -> 8 | I28: =I27+1 -> 2031 | J28: {=INDEX('27.5-Year'!$A$1:$M$32,MATCH(_27.5_Year_Post_CS[[#This Row],[Year No.]],'27.5-Year'!$A:$A,0),MONTH('Study Data'!$B$6)+1)} -> 0.03636 | K28: =IF($E$11=27.5,$G$11,0) -> 0 | L28: =_27.5_Year_Post_CS[[#This Row],[Adj Basis]]*_27.5_Year_Post_CS[[#This Row],[27.5-Year Rate]] -> 0 | M28: =M27+_27.5_Year_Post_CS[[#This Row],[Annual Depreciation]] -> 0 | O28: Bonus Depreciation | P28: =INDEX(Definitions!$C$2:$C$12,MATCH('Client Summary'!$G$13,Definitions!$A$2:$A$12,1)) -> 0.6 | Q28: =G12*$P$28 -> 0 | V28: =V27+1 -> 8 | W28: =W27+1 -> 2031 | X28: 0.0446 | Y28: =$G$13-$X$30 -> 0 | Z28: =_7_Year_Post_CS[[#This Row],[Basis]]*_7_Year_Post_CS[[#This Row],[7-Year Rate]] -> 0 | AA28: =AA27+_7_Year_Post_CS[[#This Row],[Annual Depreciation]] -> 0 | AC28: =AC27+1 -> 8 | AD28: =AD27+1 -> 2031 | AE28: 0.059 | AF28: =$G$14-$AE$38 -> 0 | AG28: =_15_Year_Post_CS[[#This Row],[Basis]]*_15_Year_Post_CS[[#This Row],[15-Year Rate]] -> 0 | AH28: =AH27+_15_Year_Post_CS[[#This Row],[Annual Depreciation]] -> 0
A29: =A28+1 -> 9 | B29: =B28+1 -> 2032 | C29: {=INDEX('27.5-Year'!$A$1:$M$32,MATCH(_27.5_Year_Original[[#This Row],[Year No.]],'27.5-Year'!$A:$A,0),MONTH('Study Data'!$B$6)+1)} -> 0.03636 | D29: =IF($E$11=27.5,$D$11,0) -> 0 | E29: =_27.5_Year_Original[[#This Row],[Original Basis]]*_27.5_Year_Original[[#This Row],[27.5-Year Rate]] -> 0 | F29: =F28+_27.5_Year_Original[[#This Row],[Annual Depreciation]] -> 0 | H29: =H28+1 -> 9 | I29: =I28+1 -> 2032 | J29: {=INDEX('27.5-Year'!$A$1:$M$32,MATCH(_27.5_Year_Post_CS[[#This Row],[Year No.]],'27.5-Year'!$A:$A,0),MONTH('Study Data'!$B$6)+1)} -> 0.03636 | K29: =IF($E$11=27.5,$G$11,0) -> 0 | L29: =_27.5_Year_Post_CS[[#This Row],[Adj Basis]]*_27.5_Year_Post_CS[[#This Row],[27.5-Year Rate]] -> 0 | M29: =M28+_27.5_Year_Post_CS[[#This Row],[Annual Depreciation]] -> 0 | AC29: =AC28+1 -> 9 | AD29: =AD28+1 -> 2032 | AE29: 0.0591 | AF29: =$G$14-$AE$38 -> 0 | AG29: =_15_Year_Post_CS[[#This Row],[Basis]]*_15_Year_Post_CS[[#This Row],[15-Year Rate]] -> 0 | AH29: =AH28+_15_Year_Post_CS[[#This Row],[Annual Depreciation]] -> 0
A30: =A29+1 -> 10 | B30: =B29+1 -> 2033 | C30: {=INDEX('27.5-Year'!$A$1:$M$32,MATCH(_27.5_Year_Original[[#This Row],[Year No.]],'27.5-Year'!$A:$A,0),MONTH('Study Data'!$B$6)+1)} -> 0.03637 | D30: =IF($E$11=27.5,$D$11,0) -> 0 | E30: =_27.5_Year_Original[[#This Row],[Original Basis]]*_27.5_Year_Original[[#This Row],[27.5-Year Rate]] -> 0 | F30: =F29+_27.5_Year_Original[[#This Row],[Annual Depreciation]] -> 0 | H30: =H29+1 -> 10 | I30: =I29+1 -> 2033 | J30: {=INDEX('27.5-Year'!$A$1:$M$32,MATCH(_27.5_Year_Post_CS[[#This Row],[Year No.]],'27.5-Year'!$A:$A,0),MONTH('Study Data'!$B$6)+1)} -> 0.03637 | K30: =IF($E$11=27.5,$G$11,0) -> 0 | L30: =_27.5_Year_Post_CS[[#This Row],[Adj Basis]]*_27.5_Year_Post_CS[[#This Row],[27.5-Year Rate]] -> 0 | M30: =M29+_27.5_Year_Post_CS[[#This Row],[Annual Depreciation]] -> 0 | V30: Bonus Depreciation | W30: =INDEX(Definitions!$C$2:$C$12,MATCH('Client Summary'!$G$13,Definitions!$A$2:$A$12,1)) -> 0.6 | X30: =$G$13*$W$30 -> 0 | AC30: =AC29+1 -> 10 | AD30: =AD29+1 -> 2033 | AE30: 0.059 | AF30: =$G$14-$AE$38 -> 0 | AG30: =_15_Year_Post_CS[[#This Row],[Basis]]*_15_Year_Post_CS[[#This Row],[15-Year Rate]] -> 0 | AH30: =AH29+_15_Year_Post_CS[[#This Row],[Annual Depreciation]] -> 0
A31: =A30+1 -> 11 | B31: =B30+1 -> 2034 | C31: {=INDEX('27.5-Year'!$A$1:$M$32,MATCH(_27.5_Year_Original[[#This Row],[Year No.]],'27.5-Year'!$A:$A,0),MONTH('Study Data'!$B$6)+1)} -> 0.03636 | D31: =IF($E$11=27.5,$D$11,0) -> 0 | E31: =_27.5_Year_Original[[#This Row],[Original Basis]]*_27.5_Year_Original[[#This Row],[27.5-Year Rate]] -> 0 | F31: =F30+_27.5_Year_Original[[#This Row],[Annual Depreciation]] -> 0 | H31: =H30+1 -> 11 | I31: =I30+1 -> 2034 | J31: {=INDEX('27.5-Year'!$A$1:$M$32,MATCH(_27.5_Year_Post_CS[[#This Row],[Year No.]],'27.5-Year'!$A:$A,0),MONTH('Study Data'!$B$6)+1)} -> 0.03636 | K31: =IF($E$11=27.5,$G$11,0) -> 0 | L31: =_27.5_Year_Post_CS[[#This Row],[Adj Basis]]*_27.5_Year_Post_CS[[#This Row],[27.5-Year Rate]] -> 0 | M31: =M30+_27.5_Year_Post_CS[[#This Row],[Annual Depreciation]] -> 0 | AC31: =AC30+1 -> 11 | AD31: =AD30+1 -> 2034 | AE31: 0.0591 | AF31: =$G$14-$AE$38 -> 0 | AG31: =_15_Year_Post_CS[[#This Row],[Basis]]*_15_Year_Post_CS[[#This Row],[15-Year Rate]] -> 0 | AH31: =AH30+_15_Year_Post_CS[[#This Row],[Annual Depreciation]] -> 0
A32: =A31+1 -> 12 | B32: =B31+1 -> 2035 | C32: {=INDEX('27.5-Year'!$A$1:$M$32,MATCH(_27.5_Year_Original[[#This Row],[Year No.]],'27.5-Year'!$A:$A,0),MONTH('Study Data'!$B$6)+1)} -> 0.03637 | D32: =IF($E$11=27.5,$D$11,0) -> 0 | E32: =_27.5_Year_Original[[#This Row],[Original Basis]]*_27.5_Year_Original[[#This Row],[27.5-Year Rate]] -> 0 | F32: =F31+_27.5_Year_Original[[#This Row],[Annual Depreciation]] -> 0 | H32: =H31+1 -> 12 | I32: =I31+1 -> 2035 | J32: {=INDEX('27.5-Year'!$A$1:$M$32,MATCH(_27.5_Year_Post_CS[[#This Row],[Year No.]],'27.5-Year'!$A:$A,0),MONTH('Study Data'!$B$6)+1)} -> 0.03637 | K32: =IF($E$11=27.5,$G$11,0) -> 0 | L32: =_27.5_Year_Post_CS[[#This Row],[Adj Basis]]*_27.5_Year_Post_CS[[#This Row],[27.5-Year Rate]] -> 0 | M32: =M31+_27.5_Year_Post_CS[[#This Row],[Annual Depreciation]] -> 0 | AC32: =AC31+1 -> 12 | AD32: =AD31+1 -> 2035 | AE32: 0.059 | AF32: =$G$14-$AE$38 -> 0 | AG32: =_15_Year_Post_CS[[#This Row],[Basis]]*_15_Year_Post_CS[[#This Row],[15-Year Rate]] -> 0 | AH32: =AH31+_15_Year_Post_CS[[#This Row],[Annual Depreciation]] -> 0
A33: =A32+1 -> 13 | B33: =B32+1 -> 2036 | C33: {=INDEX('27.5-Year'!$A$1:$M$32,MATCH(_27.5_Year_Original[[#This Row],[Year No.]],'27.5-Year'!$A:$A,0),MONTH('Study Data'!$B$6)+1)} -> 0.03636 | D33: =IF($E$11=27.5,$D$11,0) -> 0 | E33: =_27.5_Year_Original[[#This Row],[Original Basis]]*_27.5_Year_Original[[#This Row],[27.5-Year Rate]] -> 0 | F33: =F32+_27.5_Year_Original[[#This Row],[Annual Depreciation]] -> 0 | H33: =H32+1 -> 13 | I33: =I32+1 -> 2036 | J33: {=INDEX('27.5-Year'!$A$1:$M$32,MATCH(_27.5_Year_Post_CS[[#This Row],[Year No.]],'27.5-Year'!$A:$A,0),MONTH('Study Data'!$B$6)+1)} -> 0.03636 | K33: =IF($E$11=27.5,$G$11,0) -> 0 | L33: =_27.5_Year_Post_CS[[#This Row],[Adj Basis]]*_27.5_Year_Post_CS[[#This Row],[27.5-Year Rate]] -> 0 | M33: =M32+_27.5_Year_Post_CS[[#This Row],[Annual Depreciation]] -> 0 | AC33: =AC32+1 -> 13 | AD33: =AD32+1 -> 2036 | AE33: 0.0591 | AF33: =$G$14-$AE$38 -> 0 | AG33: =_15_Year_Post_CS[[#This Row],[Basis]]*_15_Year_Post_CS[[#This Row],[15-Year Rate]] -> 0 | AH33: =AH32+_15_Year_Post_CS[[#This Row],[Annual Depreciation]] -> 0
A34: =A33+1 -> 14 | B34: =B33+1 -> 2037 | C34: {=INDEX('27.5-Year'!$A$1:$M$32,MATCH(_27.5_Year_Original[[#This Row],[Year No.]],'27.5-Year'!$A:$A,0),MONTH('Study Data'!$B$6)+1)} -> 0.03637 | D34: =IF($E$11=27.5,$D$11,0) -> 0 | E34: =_27.5_Year_Original[[#This Row],[Original Basis]]*_27.5_Year_Original[[#This Row],[27.5-Year Rate]] -> 0 | F34: =F33+_27.5_Year_Original[[#This Row],[Annual Depreciation]] -> 0 | H34: =H33+1 -> 14 | I34: =I33+1 -> 2037 | J34: {=INDEX('27.5-Year'!$A$1:$M$32,MATCH(_27.5_Year_Post_CS[[#This Row],[Year No.]],'27.5-Year'!$A:$A,0),MONTH('Study Data'!$B$6)+1)} -> 0.03637 | K34: =IF($E$11=27.5,$G$11,0) -> 0 | L34: =_27.5_Year_Post_CS[[#This Row],[Adj Basis]]*_27.5_Year_Post_CS[[#This Row],[27.5-Year Rate]] -> 0 | M34: =M33+_27.5_Year_Post_CS[[#This Row],[Annual Depreciation]] -> 0 | AC34: =AC33+1 -> 14 | AD34: =AD33+1 -> 2037 | AE34: 0.059 | AF34: =$G$14-$AE$38 -> 0 | AG34: =_15_Year_Post_CS[[#This Row],[Basis]]*_15_Year_Post_CS[[#This Row],[15-Year Rate]] -> 0 | AH34: =AH33+_15_Year_Post_CS[[#This Row],[Annual Depreciation]] -> 0
A35: =A34+1 -> 15 | B35: =B34+1 -> 2038 | C35: {=INDEX('27.5-Year'!$A$1:$M$32,MATCH(_27.5_Year_Original[[#This Row],[Year No.]],'27.5-Year'!$A:$A,0),MONTH('Study Data'!$B$6)+1)} -> 0.03636 | D35: =IF($E$11=27.5,$D$11,0) -> 0 | E35: =_27.5_Year_Original[[#This Row],[Original Basis]]*_27.5_Year_Original[[#This Row],[27.5-Year Rate]] -> 0 | F35: =F34+_27.5_Year_Original[[#This Row],[Annual Depreciation]] -> 0 | H35: =H34+1 -> 15 | I35: =I34+1 -> 2038 | J35: {=INDEX('27.5-Year'!$A$1:$M$32,MATCH(_27.5_Year_Post_CS[[#This Row],[Year No.]],'27.5-Year'!$A:$A,0),MONTH('Study Data'!$B$6)+1)} -> 0.03636 | K35: =IF($E$11=27.5,$G$11,0) -> 0 | L35: =_27.5_Year_Post_CS[[#This Row],[Adj Basis]]*_27.5_Year_Post_CS[[#This Row],[27.5-Year Rate]] -> 0 | M35: =M34+_27.5_Year_Post_CS[[#This Row],[Annual Depreciation]] -> 0 | AC35: =AC34+1 -> 15 | AD35: =AD34+1 -> 2038 | AE35: 0.0591 | AF35: =$G$14-$AE$38 -> 0 | AG35: =_15_Year_Post_CS[[#This Row],[Basis]]*_15_Year_Post_CS[[#This Row],[15-Year Rate]] -> 0 | AH35: =AH34+_15_Year_Post_CS[[#This Row],[Annual Depreciation]] -> 0
A36: =A35+1 -> 16 | B36: =B35+1 -> 2039 | C36: {=INDEX('27.5-Year'!$A$1:$M$32,MATCH(_27.5_Year_Original[[#This Row],[Year No.]],'27.5-Year'!$A:$A,0),MONTH('Study Data'!$B$6)+1)} -> 0.03637 | D36: =IF($E$11=27.5,$D$11,0) -> 0 | E36: =_27.5_Year_Original[[#This Row],[Original Basis]]*_27.5_Year_Original[[#This Row],[27.5-Year Rate]] -> 0 | F36: =F35+_27.5_Year_Original[[#This Row],[Annual Depreciation]] -> 0 | H36: =H35+1 -> 16 | I36: =I35+1 -> 2039 | J36: {=INDEX('27.5-Year'!$A$1:$M$32,MATCH(_27.5_Year_Post_CS[[#This Row],[Year No.]],'27.5-Year'!$A:$A,0),MONTH('Study Data'!$B$6)+1)} -> 0.03637 | K36: =IF($E$11=27.5,$G$11,0) -> 0 | L36: =_27.5_Year_Post_CS[[#This Row],[Adj Basis]]*_27.5_Year_Post_CS[[#This Row],[27.5-Year Rate]] -> 0 | M36: =M35+_27.5_Year_Post_CS[[#This Row],[Annual Depreciation]] -> 0 | AC36: =AC35+1 -> 16 | AD36: =AD35+1 -> 2039 | AE36: 0.0295 | AF36: =$G$14-$AE$38 -> 0 | AG36: =_15_Year_Post_CS[[#This Row],[Basis]]*_15_Year_Post_CS[[#This Row],[15-Year Rate]] -> 0 | AH36: =AH35+_15_Year_Post_CS[[#This Row],[Annual Depreciation]] -> 0
A37: =A36+1 -> 17 | B37: =B36+1 -> 2040 | C37: {=INDEX('27.5-Year'!$A$1:$M$32,MATCH(_27.5_Year_Original[[#This Row],[Year No.]],'27.5-Year'!$A:$A,0),MONTH('Study Data'!$B$6)+1)} -> 0.03636 | D37: =IF($E$11=27.5,$D$11,0) -> 0 | E37: =_27.5_Year_Original[[#This Row],[Original Basis]]*_27.5_Year_Original[[#This Row],[27.5-Year Rate]] -> 0 | F37: =F36+_27.5_Year_Original[[#This Row],[Annual Depreciation]] -> 0 | H37: =H36+1 -> 17 | I37: =I36+1 -> 2040 | J37: {=INDEX('27.5-Year'!$A$1:$M$32,MATCH(_27.5_Year_Post_CS[[#This Row],[Year No.]],'27.5-Year'!$A:$A,0),MONTH('Study Data'!$B$6)+1)} -> 0.03636 | K37: =IF($E$11=27.5,$G$11,0) -> 0 | L37: =_27.5_Year_Post_CS[[#This Row],[Adj Basis]]*_27.5_Year_Post_CS[[#This Row],[27.5-Year Rate]] -> 0 | M37: =M36+_27.5_Year_Post_CS[[#This Row],[Annual Depreciation]] -> 0
A38: =A37+1 -> 18 | B38: =B37+1 -> 2041 | C38: {=INDEX('27.5-Year'!$A$1:$M$32,MATCH(_27.5_Year_Original[[#This Row],[Year No.]],'27.5-Year'!$A:$A,0),MONTH('Study Data'!$B$6)+1)} -> 0.03637 | D38: =IF($E$11=27.5,$D$11,0) -> 0 | E38: =_27.5_Year_Original[[#This Row],[Original Basis]]*_27.5_Year_Original[[#This Row],[27.5-Year Rate]] -> 0 | F38: =F37+_27.5_Year_Original[[#This Row],[Annual Depreciation]] -> 0 | H38: =H37+1 -> 18 | I38: =I37+1 -> 2041 | J38: {=INDEX('27.5-Year'!$A$1:$M$32,MATCH(_27.5_Year_Post_CS[[#This Row],[Year No.]],'27.5-Year'!$A:$A,0),MONTH('Study Data'!$B$6)+1)} -> 0.03637 | K38: =IF($E$11=27.5,$G$11,0) -> 0 | L38: =_27.5_Year_Post_CS[[#This Row],[Adj Basis]]*_27.5_Year_Post_CS[[#This Row],[27.5-Year Rate]] -> 0 | M38: =M37+_27.5_Year_Post_CS[[#This Row],[Annual Depreciation]] -> 0 | AC38: Bonus Depreciation | AD38: =INDEX(Definitions!$C$2:$C$12,MATCH('Client Summary'!$G$13,Definitions!$A$2:$A$12,1)) -> 0.6 | AE38: =$G$14*$AD$38 -> 0
A39: =A38+1 -> 19 | B39: =B38+1 -> 2042 | C39: {=INDEX('27.5-Year'!$A$1:$M$32,MATCH(_27.5_Year_Original[[#This Row],[Year No.]],'27.5-Year'!$A:$A,0),MONTH('Study Data'!$B$6)+1)} -> 0.03636 | D39: =IF($E$11=27.5,$D$11,0) -> 0 | E39: =_27.5_Year_Original[[#This Row],[Original Basis]]*_27.5_Year_Original[[#This Row],[27.5-Year Rate]] -> 0 | F39: =F38+_27.5_Year_Original[[#This Row],[Annual Depreciation]] -> 0 | H39: =H38+1 -> 19 | I39: =I38+1 -> 2042 | J39: {=INDEX('27.5-Year'!$A$1:$M$32,MATCH(_27.5_Year_Post_CS[[#This Row],[Year No.]],'27.5-Year'!$A:$A,0),MONTH('Study Data'!$B$6)+1)} -> 0.03636 | K39: =IF($E$11=27.5,$G$11,0) -> 0 | L39: =_27.5_Year_Post_CS[[#This Row],[Adj Basis]]*_27.5_Year_Post_CS[[#This Row],[27.5-Year Rate]] -> 0 | M39: =M38+_27.5_Year_Post_CS[[#This Row],[Annual Depreciation]] -> 0
A40: =A39+1 -> 20 | B40: =B39+1 -> 2043 | C40: {=INDEX('27.5-Year'!$A$1:$M$32,MATCH(_27.5_Year_Original[[#This Row],[Year No.]],'27.5-Year'!$A:$A,0),MONTH('Study Data'!$B$6)+1)} -> 0.03637 | D40: =IF($E$11=27.5,$D$11,0) -> 0 | E40: =_27.5_Year_Original[[#This Row],[Original Basis]]*_27.5_Year_Original[[#This Row],[27.5-Year Rate]] -> 0 | F40: =F39+_27.5_Year_Original[[#This Row],[Annual Depreciation]] -> 0 | H40: =H39+1 -> 20 | I40: =I39+1 -> 2043 | J40: {=INDEX('27.5-Year'!$A$1:$M$32,MATCH(_27.5_Year_Post_CS[[#This Row],[Year No.]],'27.5-Year'!$A:$A,0),MONTH('Study Data'!$B$6)+1)} -> 0.03637 | K40: =IF($E$11=27.5,$G$11,0) -> 0 | L40: =_27.5_Year_Post_CS[[#This Row],[Adj Basis]]*_27.5_Year_Post_CS[[#This Row],[27.5-Year Rate]] -> 0 | M40: =M39+_27.5_Year_Post_CS[[#This Row],[Annual Depreciation]] -> 0
A41: =A40+1 -> 21 | B41: =B40+1 -> 2044 | C41: {=INDEX('27.5-Year'!$A$1:$M$32,MATCH(_27.5_Year_Original[[#This Row],[Year No.]],'27.5-Year'!$A:$A,0),MONTH('Study Data'!$B$6)+1)} -> 0.03636 | D41: =IF($E$11=27.5,$D$11,0) -> 0 | E41: =_27.5_Year_Original[[#This Row],[Original Basis]]*_27.5_Year_Original[[#This Row],[27.5-Year Rate]] -> 0 | F41: =F40+_27.5_Year_Original[[#This Row],[Annual Depreciation]] -> 0 | H41: =H40+1 -> 21 | I41: =I40+1 -> 2044 | J41: {=INDEX('27.5-Year'!$A$1:$M$32,MATCH(_27.5_Year_Post_CS[[#This Row],[Year No.]],'27.5-Year'!$A:$A,0),MONTH('Study Data'!$B$6)+1)} -> 0.03636 | K41: =IF($E$11=27.5,$G$11,0) -> 0 | L41: =_27.5_Year_Post_CS[[#This Row],[Adj Basis]]*_27.5_Year_Post_CS[[#This Row],[27.5-Year Rate]] -> 0 | M41: =M40+_27.5_Year_Post_CS[[#This Row],[Annual Depreciation]] -> 0
A42: =A41+1 -> 22 | B42: =B41+1 -> 2045 | C42: {=INDEX('27.5-Year'!$A$1:$M$32,MATCH(_27.5_Year_Original[[#This Row],[Year No.]],'27.5-Year'!$A:$A,0),MONTH('Study Data'!$B$6)+1)} -> 0.03637 | D42: =IF($E$11=27.5,$D$11,0) -> 0 | E42: =_27.5_Year_Original[[#This Row],[Original Basis]]*_27.5_Year_Original[[#This Row],[27.5-Year Rate]] -> 0 | F42: =F41+_27.5_Year_Original[[#This Row],[Annual Depreciation]] -> 0 | H42: =H41+1 -> 22 | I42: =I41+1 -> 2045 | J42: {=INDEX('27.5-Year'!$A$1:$M$32,MATCH(_27.5_Year_Post_CS[[#This Row],[Year No.]],'27.5-Year'!$A:$A,0),MONTH('Study Data'!$B$6)+1)} -> 0.03637 | K42: =IF($E$11=27.5,$G$11,0) -> 0 | L42: =_27.5_Year_Post_CS[[#This Row],[Adj Basis]]*_27.5_Year_Post_CS[[#This Row],[27.5-Year Rate]] -> 0 | M42: =M41+_27.5_Year_Post_CS[[#This Row],[Annual Depreciation]] -> 0
A43: =A42+1 -> 23 | B43: =B42+1 -> 2046 | C43: {=INDEX('27.5-Year'!$A$1:$M$32,MATCH(_27.5_Year_Original[[#This Row],[Year No.]],'27.5-Year'!$A:$A,0),MONTH('Study Data'!$B$6)+1)} -> 0.03636 | D43: =IF($E$11=27.5,$D$11,0) -> 0 | E43: =_27.5_Year_Original[[#This Row],[Original Basis]]*_27.5_Year_Original[[#This Row],[27.5-Year Rate]] -> 0 | F43: =F42+_27.5_Year_Original[[#This Row],[Annual Depreciation]] -> 0 | H43: =H42+1 -> 23 | I43: =I42+1 -> 2046 | J43: {=INDEX('27.5-Year'!$A$1:$M$32,MATCH(_27.5_Year_Post_CS[[#This Row],[Year No.]],'27.5-Year'!$A:$A,0),MONTH('Study Data'!$B$6)+1)} -> 0.03636 | K43: =IF($E$11=27.5,$G$11,0) -> 0 | L43: =_27.5_Year_Post_CS[[#This Row],[Adj Basis]]*_27.5_Year_Post_CS[[#This Row],[27.5-Year Rate]] -> 0 | M43: =M42+_27.5_Year_Post_CS[[#This Row],[Annual Depreciation]] -> 0
A44: =A43+1 -> 24 | B44: =B43+1 -> 2047 | C44: {=INDEX('27.5-Year'!$A$1:$M$32,MATCH(_27.5_Year_Original[[#This Row],[Year No.]],'27.5-Year'!$A:$A,0),MONTH('Study Data'!$B$6)+1)} -> 0.03637 | D44: =IF($E$11=27.5,$D$11,0) -> 0 | E44: =_27.5_Year_Original[[#This Row],[Original Basis]]*_27.5_Year_Original[[#This Row],[27.5-Year Rate]] -> 0 | F44: =F43+_27.5_Year_Original[[#This Row],[Annual Depreciation]] -> 0 | H44: =H43+1 -> 24 | I44: =I43+1 -> 2047 | J44: {=INDEX('27.5-Year'!$A$1:$M$32,MATCH(_27.5_Year_Post_CS[[#This Row],[Year No.]],'27.5-Year'!$A:$A,0),MONTH('Study Data'!$B$6)+1)} -> 0.03637 | K44: =IF($E$11=27.5,$G$11,0) -> 0 | L44: =_27.5_Year_Post_CS[[#This Row],[Adj Basis]]*_27.5_Year_Post_CS[[#This Row],[27.5-Year Rate]] -> 0 | M44: =M43+_27.5_Year_Post_CS[[#This Row],[Annual Depreciation]] -> 0
A45: =A44+1 -> 25 | B45: =B44+1 -> 2048 | C45: {=INDEX('27.5-Year'!$A$1:$M$32,MATCH(_27.5_Year_Original[[#This Row],[Year No.]],'27.5-Year'!$A:$A,0),MONTH('Study Data'!$B$6)+1)} -> 0.03636 | D45: =IF($E$11=27.5,$D$11,0) -> 0 | E45: =_27.5_Year_Original[[#This Row],[Original Basis]]*_27.5_Year_Original[[#This Row],[27.5-Year Rate]] -> 0 | F45: =F44+_27.5_Year_Original[[#This Row],[Annual Depreciation]] -> 0 | H45: =H44+1 -> 25 | I45: =I44+1 -> 2048 | J45: {=INDEX('27.5-Year'!$A$1:$M$32,MATCH(_27.5_Year_Post_CS[[#This Row],[Year No.]],'27.5-Year'!$A:$A,0),MONTH('Study Data'!$B$6)+1)} -> 0.03636 | K45: =IF($E$11=27.5,$G$11,0) -> 0 | L45: =_27.5_Year_Post_CS[[#This Row],[Adj Basis]]*_27.5_Year_Post_CS[[#This Row],[27.5-Year Rate]] -> 0 | M45: =M44+_27.5_Year_Post_CS[[#This Row],[Annual Depreciation]] -> 0
...

Sheet Definitions
A1: Bonus | G1: 5-Yr | H1: 15-Yr | I1: Total
A2: 37145 | B2: 37746 | C2: 0.3 | E2: --
A3: 37747 | B3: 38352 | C3: 0.5 | E3: Custom | F3: =E3 -> Custom | G3: 0 | H3: 0 | I3: =SUM(G3:H3) -> 0 | K3: --
A4: 38353 | B4: 39447 | C4: 0 | E4: Single Family Residence | F4: =E4 -> Single Family Residence | G4: 0.12 | H4: 0.08 | I4: =SUM(G4:H4) -> 0.2 | K4: Custom
A5: 39448 | B5: 40429 | C5: 0.5 | E5: Duplex | F5: =E5 -> Duplex | G5: 0.14 | H5: 0.08 | I5: =SUM(G5:H5) -> 0.22 | K5: Single Family Residence
A6: 40430 | B6: 40908 | C6: 1 | E6: Triplex | F6: =E6 -> Triplex | G6: 0.14 | H6: 0.08 | I6: =SUM(G6:H6) -> 0.22 | K6: Duplex
A7: 40909 | B7: 43005 | C7: 0.5 | E7: 4-Plex | F7: =E7 -> 4-Plex | G7: 0.14 | H7: 0.08 | I7: =SUM(G7:H7) -> 0.22 | K7: Triplex
A8: 43006 | B8: 44926 | C8: 1 | E8: Townhome | F8: =E8 -> Townhome | G8: 0.12 | H8: 0.08 | I8: =SUM(G8:H8) -> 0.2 | K8: 4-Plex
A9: 44927 | B9: 45291 | C9: 0.8 | E9: Condo | F9: =E9 -> Condo | G9: 0.17 | H9: 0 | I9: =SUM(G9:H9) -> 0.17 | K9: Townhome
A10: 45292 | B10: 45657 | C10: 0.6 | E10: Apartment | F10: =E10 -> Apartment | G10: 0.14 | H10: 0.08 | I10: =SUM(G10:H10) -> 0.22 | K10: Condo
A11: 45658 | B11: 45676 | C11: 0.4 | E11: Mixed-Use | F11: =E11 -> Mixed-Use | G11: 0.14 | H11: 0.08 | I11: =SUM(G11:H11) -> 0.22 | K11: Apartment
A12: 45677 | B12: 47483 | C12: 1 | E12: STR Single Family Residence | F12: =E12 -> STR Single Family Residence | G12: 0.12 | H12: 0.08 | I12: =SUM(G12:H12) -> 0.2 | K12: Mixed-Use
E13: STR Condo | F13: =E13 -> STR Condo | G13: 0.17 | H13: 0 | I13: =SUM(G13:H13) -> 0.17 | K13: STR Single Family Residence
E14: Single Family Residence Economy | F14: Single Family Residence | G14: 0.12 | H14: 0.08 | I14: =SUM(G14:H14) -> 0.2 | K14: STR Condo
E15: STR Single Family Residence Economy | F15: STR Single Family Residence | G15: 0.12 | H15: 0.08 | I15: =SUM(G15:H15) -> 0.2 | K15: Assisted Living Facility
E16: Single Family Residence Builders Choice | F16: Single Family Residence | G16: 0.14 | H16: 0.1 | I16: =SUM(G16:H16) -> 0.24 | K16: Grocery Store
E17: STR Single Family Residence Builders Choice | F17: STR Single Family Residence | G17: 0.14 | H17: 0.1 | I17: =SUM(G17:H17) -> 0.24 | K17: Medical Center
E18: Single Family Residence Custom | F18: Single Family Residence | G18: 0.16 | H18: 0.12 | I18: =SUM(G18:H18) -> 0.28 | K18: Office Condo
E19: STR Single Family Residence Custom | F19: STR Single Family Residence | G19: 0.16 | H19: 0.12 | I19: =SUM(G19:H19) -> 0.28 | K19: Office Building
E20: Condo | F20: Condo | G20: 0.17 | H20: 0 | I20: =SUM(G20:H20) -> 0.17 | K20: Restaurant
E21: STR Condo | F21: STR Condo | G21: 0.17 | H21: 0 | I21: =SUM(G21:H21) -> 0.17 | K21: Warehouse
E22: Multifamily Residence Economy | F22: Multifamily Residence | G22: 0.14 | H22: 0.08 | I22: =SUM(G22:H22) -> 0.22
E23: Multifamily Residence Builders Choice | F23: Multifamily Residence | G23: 0.16 | H23: 0.1 | I23: =SUM(G23:H23) -> 0.26
E24: Assisted Living Facility | F24: Assisted Living Facility | G24: 0.15 | H24: 0.1 | I24: =SUM(G24:H24) -> 0.25
E25: Auto Repair | F25: Auto Repair | G25: 0.15 | H25: 0.1 | I25: =SUM(G25:H25) -> 0.25
E26: Car Wash | F26: Car Wash | G26: 0.05 | H26: 0.95 | I26: =SUM(G26:H26) -> 1
E27: Daycare Facility | F27: Daycare Facility | G27: 0.1 | H27: 0.1 | I27: =SUM(G27:H27) -> 0.2
E28: Fitness Center | F28: Fitness Center | G28: 0.2 | H28: 0.05 | I28: =SUM(G28:H28) -> 0.25
E29: Grocery Store | F29: Grocery Store | G29: 0.2 | H29: 0.15 | I29: =SUM(G29:H29) -> 0.35
E30: Hotel - Full Service | F30: Hotel | G30: 0.19 | H30: 0.06 | I30: =SUM(G30:H30) -> 0.25
E31: Hotel - Ltd Service | F31: Hotel | G31: 0.17 | H31: 0.1 | I31: =SUM(G31:H31) -> 0.27
E32: Strip Mall | F32: Strip Mall | G32: 0.12 | H32: 0.13 | I32: =SUM(G32:H32) -> 0.25
E33: Marina | F33: Marina | G33: 0.15 | H33: 0.15 | I33: =SUM(G33:H33) -> 0.3
... E44: Warehouse Facility | F44: Warehouse | G44: 0.02 | H44: 0.12 | I44: =SUM(G44:H44) -> 0.14

Sheet Client Summary
A1: #VALUE!
A7: US Tax Advisors Group, Inc. Modeling Calculation
A9: Enclosed is the result of a US Tax Advisors Group, Inc. (USTAGI) Construction Cost Modeling Calculation which utilizes a national construction cost database to model the building’s quantities and costs. The data is then statistically segregated, as appropriate, between section 1245 and 1250 property.
C12: Property Address: | G12: 861 E 800 S, Salt Lake City, UT 84102
C13: Date Placed in Service: | G13: 45292 | M13: Tax Year | N13: 2025
C14: Cost Basis: | G14: 0
C15: Land Allocation: | G15: 0
C16: Building Basis: | G16: =G14-G15 -> 0
C17: Improvements included in the Study: | G17: 0
C18: Basis for Cost Segregation: | G18: =G16+G17 -> 0
C19: ="Accumulated Depreciation as of 12/31/"&'Study Data'!$B$5-1&":" -> Accumulated Depreciation as of 12/31/2024: | G19: 0
C20: Occupancy Type: | G20: Residential
C21: Building Use: | G21: Single Family Residence
A24: Based on these results, the Federal Tax Depreciation Schedule should be revised as follows:
A25: Asset ID | B25: Property Description | E25: Date Acquired | F25: Basis | G25: Life (Years) | H25: Depr Method | I25: Conv | J25: ="Accumulated Depreciation as of 12/31/"&'Study Data'!$B$5-1 -> Accumulated Depreciation as of 12/31/2024 | L25: Depreciation Adjustment
A26: 1 | B26: Building | E26: =+$G$13 -> 45292 | F26: =_xlfn.IFNA(ROUND(Calculator!C5,0),0) -> 0 | G26: =IF($G$20="Residential",27.5,39) -> 27.5 | H26: SL | I26: Mid-Month | J26: =ROUND(IF(F26=0,0,'Study Data'!K11),0) -> 0 | L26: =J26-G19 -> 0
A27: 1.1 | B27: Asset Class 57.0 - Distributive Trades and Services | E27: =+$G$13 -> 45292 | F27: =_xlfn.IFNA(ROUND(Calculator!C7,0),0) -> 0 | G27: 5 | H27: 200DB | I27: Half-Year | J27: =ROUND(IF(F27=0,0,'Study Data'!K12),0) -> 0 | L27: =J27 -> 0
A28: 1.2 | B28: Asset Class 0.11 - Office Furniture, Fixtures and Equipment | E28: =+$G$13 -> 45292 | F28: 0 | G28: 7 | H28: 200DB | I28: Half-Year | J28: =ROUND(IF(F28=0,0,'Study Data'!K13),0) -> 0 | L28: =J28 -> 0
A29: 1.3 | B29: Asset Class 0.30 - Land Improvements | E29: =+$G$13 -> 45292 | F29: =_xlfn.IFNA(ROUND(Calculator!C6,0),0) -> 0 | G29: 15 | H29: 150DB | I29: Half-Year | J29: =ROUND(IF(F29=0,0,'Study Data'!K14),0) -> 0 | L29: =J29 -> 0
B30: Totals | F30: =SUM(F26:F29) -> 0 | J30: =SUM(J26:K29) -> 0 | L30: =SUM(L26:M29) -> 0
A32: This Construction Cost Modeling Calculation along with the Schedules represent the Cost Segregation Report. If the property was placed into service in a prior tax year you will need to file Form 3115 along with the Form 3115 Attachment.
M35: =SUM(F27:F29) -> 0
A38: Form 3115 - Attachment
A40: For Property Located at: | E40: =G12 -> 861 E 800 S, Salt Lake City, UT 84102
A41: Part II: Information For All Requests:
A42: Question 14:
A43: a) | B43: The following items were reclassified as follows:
A45: Item | H45: Date Placed in Service | J45: Original Basis
A46: Asset Class 57.0 - Distributive Trades and Services | H46: =$G$13 -> 45292 | J46: =F27 -> 0
A47: Asset Class 0.11 - Office Furniture, Fixtures, & Equipment | H47: =$G$13 -> 45292 | J47: =F28 -> 0
A48: Asset Class 0.30 - Land Improvements | H48: =$G$13 -> 45292 | J48: =F29 -> 0
A50: b) | B50: The property was currently being depreciated as Section 1250 property, and part of the building's original basis.
A51: c) | B51: The applicant proposes to reclassify the above property as personal property under 26 CFR 1.168.
A52: d) | B52: The applicant's present overall method of accounting is the | H52: Cash Method
A54: Question 15(a):
A55: The applicant's trade or business is: | F55: =IF($F$56=531110,"Lessors of Residential Buildings and Dwellings","Lessors of Nonresidential Buildings") -> Lessors of Residential Buildings and Dwellings
A56: Business Activity Code: | F56: =IF($G$20="Residential",531110,531120) -> 531110
A58: Question 16:
A59: a) | B59: Under its present method, the Applicant is claiming less depreciation than allowable on certain assets. The code section which the Applicant will depreciate or amortize
B60: property is under §168. Major categories of expenditures examined are below:
...

Sheet 27.5 Estimate
B1: #VALUE!
B7: Cost Segregation Estimate
C9: Property Address: | G9: ='Client Summary'!G12 -> 861 E 800 S, Salt Lake City, UT 84102
C10: Building Use: | G10: =_xlfn.XLOOKUP('Client Summary'!$G$21,Definitions!$E$2:$E$35,Definitions!$F$2:$F$35,0,0,1) -> Single Family Residence
C11: Date Placed in Service: | F11: ='Client Summary'!G13 -> 45292
C12: Cost Basis: | G12: ='Client Summary'!G14 -> 0
C13: Land Allocation: | D13: =IFERROR(G13/G12,"") | E13: Per Depreciation Schedule | G13: ='Client Summary'!G15 -> 0
C14: Building Basis: | G14: ='Client Summary'!G16 -> 0
C15: Improvements included in the Study: | G15: ='Client Summary'!G17 -> 0
C16: Basis for Cost Segregation: | G16: ='Client Summary'!G18 -> 0
C17: ="Accumulated Depreciation as of 12/31/"&'Study Data'!$B$5-1&":" -> Accumulated Depreciation as of 12/31/2024: | G17: ='Client Summary'!G19 -> 0
C19: Total Accelerated: | G19: =SUM($C$56:$E$56) -> 0
C20: Tax Savings Benefit at a 40% Income Tax Rate: | G20: =$G$19*40% -> 0
C22: Estimated Additional Depreciation Expense: | G22: =SUMIFS($G$27:$G$55,$B$27:$B$55,"<"&'Client Summary'!$N$13)-IF($G$17=0,SUMIFS($H$27:$H$55,$B$27:$B$55,"<"&'Client Summary'!$N$13),'27.5 Estimate'!$G$17) -> 0
C23: Tax Savings Benefit at a 40% Income Tax Rate: | G23: =$G$22*40% -> 0
B25: USTAGI estimates the following results of the Cost Segregation Study:
B26: Tax Year | C26: 5 Years Depr. with CSS | D26: 7 Years Depr. with CSS | E26: 15 Years Depr. with CSS | F26: 27.5 Years Depr. with CSS | G26: Depr. with CSS | H26: Depr. without CSS
B27: =YEAR($F$11) -> 2024 | C27: =IF('Client Summary'!$G$20="Residential",'Study Data'!T21,0) -> 0 | D27: =IF('Client Summary'!$G$20="Residential",'Study Data'!AA21,0) -> 0 | E27: =IF('Client Summary'!$G$20="Residential",'Study Data'!AH21,0) -> 0 | F27: ='Study Data'!L21 -> 0 | G27: =SUM(C27:F27) -> 0 | H27: ='Study Data'!E21 -> 0
B28: =B27+1 -> 2025 | C28: =IF('Client Summary'!$G$20="Residential",'Study Data'!S22,0) -> 0 | D28: =IF('Client Summary'!$G$20="Residential",'Study Data'!Z22,0) -> 0 | E28: =IF('Client Summary'!$G$20="Residential",'Study Data'!AG22,0) -> 0 | F28: ='Study Data'!L22 -> 0 | G28: =SUM(C28:F28) -> 0 | H28: ='Study Data'!E22 -> 0
B29: =B28+1 -> 2026 | C29: =IF('Client Summary'!$G$20="Residential",'Study Data'!S23,0) -> 0 | D29: =IF('Client Summary'!$G$20="Residential",'Study Data'!Z23,0) -> 0 | E29: =IF('Client Summary'!$G$20="Residential",'Study Data'!AG23,0) -> 0 | F29: ='Study Data'!L23 -> 0 | G29: =SUM(C29:F29) -> 0 | H29: ='Study Data'!E23 -> 0
B30: =B29+1 -> 2027 | C30: =IF('Client Summary'!$G$20="Residential",'Study Data'!S24,0) -> 0 | D30: =IF('Client Summary'!$G$20="Residential",'Study Data'!Z24,0) -> 0 | E30: =IF('Client Summary'!$G$20="Residential",'Study Data'!AG24,0) -> 0 | F30: ='Study Data'!L24 -> 0 | G30: =SUM(C30:F30) -> 0 | H30: ='Study Data'!E24 -> 0
B31: =B30+1 -> 2028 | C31: =IF('Client Summary'!$G$20="Residential",'Study Data'!S25,0) -> 0 | D31: =IF('Client Summary'!$G$20="Residential",'Study Data'!Z25,0) -> 0 | E31: =IF('Client Summary'!$G$20="Residential",'Study Data'!AG25,0) -> 0 | F31: ='Study Data'!L25 -> 0 | G31: =SUM(C31:F31) -> 0 | H31: ='Study Data'!E25 -> 0
B32: =B31+1 -> 2029 | C32: =IF('Client Summary'!$G$20="Residential",'Study Data'!S26,0) -> 0 | D32: =IF('Client Summary'!$G$20="Residential",'Study Data'!Z26,0) -> 0 | E32: =IF('Client Summary'!$G$20="Residential",'Study Data'!AG26,0) -> 0 | F32: ='Study Data'!L26 -> 0 | G32: =SUM(C32:F32) -> 0 | H32: ='Study Data'!E26 -> 0
B33: =B32+1 -> 2030 | D33: =IF('Client Summary'!$G$20="Residential",'Study Data'!Z27,0) -> 0 | E33: =IF('Client Summary'!$G$20="Residential",'Study Data'!AG27,0) -> 0 | F33: ='Study Data'!L27 -> 0 | G33: =SUM(C33:F33) -> 0 | H33: ='Study Data'!E27 -> 0
B34: =B33+1 -> 2031 | D34: =IF('Client Summary'!$G$20="Residential",'Study Data'!Z28,0) -> 0 | E34: =IF('Client Summary'!$G$20="Residential",'Study Data'!AG28,0) -> 0 | F34: ='Study Data'!L28 -> 0 | G34: =SUM(C34:F34) -> 0 | H34: ='Study Data'!E28 -> 0
B35: =B34+1 -> 2032 | E35: =IF('Client Summary'!$G$20="Residential",'Study Data'!AG29,0) -> 0 | F35: ='Study Data'!L29 -> 0 | G35: =SUM(C35:F35) -> 0 | H35: ='Study Data'!E29 -> 0
B36: =B35+1 -> 2033 | E36: =IF('Client Summary'!$G$20="Residential",'Study Data'!AG30,0) -> 0 | F36: ='Study Data'!L30 -> 0 | G36: =SUM(C36:F36) -> 0 | H36: ='Study Data'!E30 -> 0
B37: =B36+1 -> 2034 | E37: =IF('Client Summary'!$G$20="Residential",'Study Data'!AG31,0) -> 0 | F37: ='Study Data'!L31 -> 0 | G37: =SUM(C37:F37) -> 0 | H37: ='Study Data'!E31 -> 0
B38: =B37+1 -> 2035 | E38: =IF('Client Summary'!$G$20="Residential",'Study Data'!AG32,0) -> 0 | F38: ='Study Data'!L32 -> 0 | G38: =SUM(C38:F38) -> 0 | H38: ='Study Data'!E32 -> 0
B39: =B38+1 -> 2036 | E39: =IF('Client Summary'!$G$20="Residential",'Study Data'!AG33,0) -> 0 | F39: ='Study Data'!L33 -> 0 | G39: =SUM(C39:F39) -> 0 | H39: ='Study Data'!E33 -> 0
B40: =B39+1 -> 2037 | E40: =IF('Client Summary'!$G$20="Residential",'Study Data'!AG34,0) -> 0 | F40: ='Study Data'!L34 -> 0 | G40: =SUM(C40:F40) -> 0 | H40: ='Study Data'!E34 -> 0
B41: =B40+1 -> 2038 | E41: =IF('Client Summary'!$G$20="Residential",'Study Data'!AG35,0) -> 0 | F41: ='Study Data'!L35 -> 0 | G41: =SUM(C41:F41) -> 0 | H41: ='Study Data'!E35 -> 0
B42: =B41+1 -> 2039 | E42: =IF('Client Summary'!$G$20="Residential",'Study Data'!AG36,0) -> 0 | F42: ='Study Data'!L36 -> 0 | G42: =SUM(C42:F42) -> 0 | H42: ='Study Data'!E36 -> 0
B43: =B42+1 -> 2040 | F43: ='Study Data'!L37 -> 0 | G43: =SUM(C43:F43) -> 0 | H43: ='Study Data'!E37 -> 0
B44: =B43+1 -> 2041 | F44: ='Study Data'!L38 -> 0 | G44: =SUM(C44:F44) -> 0 | H44: ='Study Data'!E38 -> 0
B45: =B44+1 -> 2042 | F45: ='Study Data'!L39 -> 0 | G45: =SUM(C45:F45) -> 0 | H45: ='Study Data'!E39 -> 0
B46: =B45+1 -> 2043 | F46: ='Study Data'!L40 -> 0 | G46: =SUM(C46:F46) -> 0 | H46: ='Study Data'!E40 -> 0
B47: =B46+1 -> 2044 | F47: ='Study Data'!L41 -> 0 | G47: =SUM(C47:F47) -> 0 | H47: ='Study Data'!E41 -> 0
B48: =B47+1 -> 2045 | F48: ='Study Data'!L42 -> 0 | G48: =SUM(C48:F48) -> 0 | H48: ='Study Data'!E42 -> 0
B49: =B48+1 -> 2046 | F49: ='Study Data'!L43 -> 0 | G49: =SUM(C49:F49) -> 0 | H49: ='Study Data'!E43 -> 0
...

Sheet 39 Estimate
B1: #VALUE!
B7: Cost Segregation Estimate
C9: Property Address: | G9: ='Client Summary'!G12 -> 861 E 800 S, Salt Lake City, UT 84102
C10: Building Use: | G10: =_xlfn.XLOOKUP('Client Summary'!$G$21,Definitions!$E$2:$E$35,Definitions!$F$2:$F$35,0,0,1) -> Single Family Residence
C11: Date Placed in Service: | F11: ='Client Summary'!G13 -> 45292
C12: Cost Basis: | G12: ='Client Summary'!G14 -> 0
C13: Land Allocation: | D13: =IFERROR(G13/G12,"") | E13: Per Depreciation Schedule | G13: ='Client Summary'!G15 -> 0
C14: Building Basis: | G14: ='Client Summary'!G16 -> 0
C15: Improvements included in the Study: | G15: ='Client Summary'!G17 -> 0
C16: Basis for Cost Segregation: | G16: ='Client Summary'!G18 -> 0
C17: ="Accumulated Depreciation as of 12/31/"&'Study Data'!$B$5-1&":" -> Accumulated Depreciation as of 12/31/2024: | G17: ='Client Summary'!G19 -> 0
C19: Total Accelerated: | G19: =SUM(C68:E68) -> 0
C20: Tax Savings Benefit at a 40% Income Tax Rate: | G20: =G19*40% -> 0
C22: Estimated Additional Depreciation Expense: | G22: =SUMIFS($G$27:$G$66,$B$27:$B$66,"<2025")-IF(G17=0,SUMIFS($H$27:$H$66,$B$27:$B$66,"<2025"),G17) -> 0
C23: Tax Savings Benefit at a 40% Income Tax Rate: | G23: =$G$22*40% -> 0
B25: USTAGI estimates the following results of the Cost Segregation Study:
B26: Tax Year | C26: 5 Years Depr. with CSS | D26: 7 Years Depr. with CSS | E26: 15 Years Depr. with CSS | F26: 39 Years Depr. with CSS | G26: Depr. with CSS | H26: Depr. without CSS
B27: =YEAR($F$11) -> 2024 | C27: =IF('Client Summary'!$G$20="Commercial",'Study Data'!T21,0) -> 0 | D27: =IF('Client Summary'!$G$20="Commercial",'Study Data'!AA21,0) -> 0 | E27: =IF('Client Summary'!$G$20="Commercial",'Study Data'!AH21,0) -> 0 | F27: ='Study Data'!L55 -> 0 | G27: =SUM(C27:F27) -> 0 | H27: ='Study Data'!E55 -> 0
B28: =B27+1 -> 2025 | C28: =IF('Client Summary'!$G$20="Commercial",'Study Data'!S22,0) -> 0 | D28: =IF('Client Summary'!$G$20="Commercial",'Study Data'!Z22,0) -> 0 | E28: =IF('Client Summary'!$G$20="Commercial",'Study Data'!AG22,0) -> 0 | F28: ='Study Data'!L56 -> 0 | G28: =SUM(C28:F28) -> 0 | H28: ='Study Data'!E56 -> 0
B29: =B28+1 -> 2026 | C29: =IF('Client Summary'!$G$20="Commercial",'Study Data'!S23,0) -> 0 | D29: =IF('Client Summary'!$G$20="Commercial",'Study Data'!Z23,0) -> 0 | E29: =IF('Client Summary'!$G$20="Commercial",'Study Data'!AG23,0) -> 0 | F29: ='Study Data'!L57 -> 0 | G29: =SUM(C29:F29) -> 0 | H29: ='Study Data'!E57 -> 0
B30: =B29+1 -> 2027 | C30: =IF('Client Summary'!$G$20="Commercial",'Study Data'!S24,0) -> 0 | D30: =IF('Client Summary'!$G$20="Commercial",'Study Data'!Z24,0) -> 0 | E30: =IF('Client Summary'!$G$20="Commercial",'Study Data'!AG24,0) -> 0 | F30: ='Study Data'!L58 -> 0 | G30: =SUM(C30:F30) -> 0 | H30: ='Study Data'!E58 -> 0
B31: =B30+1 -> 2028 | C31: =IF('Client Summary'!$G$20="Commercial",'Study Data'!S25,0) -> 0 | D31: =IF('Client Summary'!$G$20="Commercial",'Study Data'!Z25,0) -> 0 | E31: =IF('Client Summary'!$G$20="Commercial",'Study Data'!AG25,0) -> 0 | F31: ='Study Data'!L59 -> 0 | G31: =SUM(C31:F31) -> 0 | H31: ='Study Data'!E59 -> 0
B32: =B31+1 -> 2029 | C32: =IF('Client Summary'!$G$20="Commercial",'Study Data'!S26,0) -> 0 | D32: =IF('Client Summary'!$G$20="Commercial",'Study Data'!Z26,0) -> 0 | E32: =IF('Client Summary'!$G$20="Commercial",'Study Data'!AG26,0) -> 0 | F32: ='Study Data'!L60 -> 0 | G32: =SUM(C32:F32) -> 0 | H32: ='Study Data'!E60 -> 0
B33: =B32+1 -> 2030 | D33: =IF('Client Summary'!$G$20="Commercial",'Study Data'!Z27,0) -> 0 | E33: =IF('Client Summary'!$G$20="Commercial",'Study Data'!AG27,0) -> 0 | F33: ='Study Data'!L61 -> 0 | G33: =SUM(C33:F33) -> 0 | H33: ='Study Data'!E61 -> 0
B34: =B33+1 -> 2031 | D34: =IF('Client Summary'!$G$20="Commercial",'Study Data'!Z28,0) -> 0 | E34: =IF('Client Summary'!$G$20="Commercial",'Study Data'!AG28,0) -> 0 | F34: ='Study Data'!L62 -> 0 | G34: =SUM(C34:F34) -> 0 | H34: ='Study Data'!E62 -> 0
B35: =B34+1 -> 2032 | E35: =IF('Client Summary'!$G$20="Commercial",'Study Data'!AG29,0) -> 0 | F35: ='Study Data'!L63 -> 0 | G35: =SUM(C35:F35) -> 0 | H35: ='Study Data'!E63 -> 0
B36: =B35+1 -> 2033 | E36: =IF('Client Summary'!$G$20="Commercial",'Study Data'!AG30,0) -> 0 | F36: ='Study Data'!L64 -> 0 | G36: =SUM(C36:F36) -> 0 | H36: ='Study Data'!E64 -> 0
B37: =B36+1 -> 2034 | E37: =IF('Client Summary'!$G$20="Commercial",'Study Data'!AG31,0) -> 0 | F37: ='Study Data'!L65 -> 0 | G37: =SUM(C37:F37) -> 0 | H37: ='Study Data'!E65 -> 0
B38: =B37+1 -> 2035 | E38: =IF('Client Summary'!$G$20="Commercial",'Study Data'!AG32,0) -> 0 | F38: ='Study Data'!L66 -> 0 | G38: =SUM(C38:F38) -> 0 | H38: ='Study Data'!E66 -> 0
B39: =B38+1 -> 2036 | E39: =IF('Client Summary'!$G$20="Commercial",'Study Data'!AG33,0) -> 0 | F39: ='Study Data'!L67 -> 0 | G39: =SUM(C39:F39) -> 0 | H39: ='Study Data'!E67 -> 0
B40: =B39+1 -> 2037 | E40: =IF('Client Summary'!$G$20="Commercial",'Study Data'!AG34,0) -> 0 | F40: ='Study Data'!L68 -> 0 | G40: =SUM(C40:F40) -> 0 | H40: ='Study Data'!E68 -> 0
B41: =B40+1 -> 2038 | E41: =IF('Client Summary'!$G$20="Commercial",'Study Data'!AG35,0) -> 0 | F41: ='Study Data'!L69 -> 0 | G41: =SUM(C41:F41) -> 0 | H41: ='Study Data'!E69 -> 0
B42: =B41+1 -> 2039 | E42: =IF('Client Summary'!$G$20="Commercial",'Study Data'!AG36,0) -> 0 | F42: ='Study Data'!L70 -> 0 | G42: =SUM(C42:F42) -> 0 | H42: ='Study Data'!E70 -> 0
B43: =B42+1 -> 2040 | F43: ='Study Data'!L71 -> 0 | G43: =SUM(C43:F43) -> 0 | H43: ='Study Data'!E71 -> 0
B44: =B43+1 -> 2041 | F44: ='Study Data'!L72 -> 0 | G44: =SUM(C44:F44) -> 0 | H44: ='Study Data'!E72 -> 0
B45: =B44+1 -> 2042 | F45: ='Study Data'!L73 -> 0 | G45: =SUM(C45:F45) -> 0 | H45: ='Study Data'!E73 -> 0
B46: =B45+1 -> 2043 | F46: ='Study Data'!L74 -> 0 | G46: =SUM(C46:F46) -> 0 | H46: ='Study Data'!E74 -> 0
B47: =B46+1 -> 2044 | F47: ='Study Data'!L75 -> 0 | G47: =SUM(C47:F47) -> 0 | H47: ='Study Data'!E75 -> 0
B48: =B47+1 -> 2045 | F48: ='Study Data'!L76 -> 0 | G48: =SUM(C48:F48) -> 0 | H48: ='Study Data'!E76 -> 0
B49: =B48+1 -> 2046 | F49: ='Study Data'!L77 -> 0 | G49: =SUM(C49:F49) -> 0 | H49: ='Study Data'!E77 -> 0
...

Sheet Real Property
AF8: Repro. Cost New | AG8: Less Depreciation | AH8: Total Cost | AI8: Source
AF9: =IFERROR(AA9*AG9,0) -> 0 | AG9: =IF(AA9=0,"",Calculator!$B$5) | AH9: =(AF9/Calculator!$B$10)*Calculator!$B$9 -> #DIV/0! | AI9: =IF(ISBLANK(AA9),"","RS Means")
AF10: =IFERROR(AA10*AG10,0) -> 0 | AG10: =IF(AA10=0,"",Calculator!$B$5) | AH10: =(AF10/Calculator!$B$10)*Calculator!$B$9 -> #DIV/0! | AI10: =IF(ISBLANK(AA10),"","RS Means")
AF11: =IFERROR(AA11*AG11,0) -> 0 | AG11: =IF(AA11=0,"",Calculator!$B$5) | AH11: =(AF11/Calculator!$B$10)*Calculator!$B$9 -> #DIV/0! | AI11: =IF(ISBLANK(AA11),"","RS Means")
AF12: =IFERROR(AA12*AG12,0) -> 0 | AG12: =IF(AA12=0,"",Calculator!$B$5) | AH12: =(AF12/Calculator!$B$10)*Calculator!$B$9 -> #DIV/0! | AI12: =IF(ISBLANK(AA12),"","RS Means")
AF13: =IFERROR(AA13*AG13,0) -> 0 | AG13: =IF(AA13=0,"",Calculator!$B$5) | AH13: =(AF13/Calculator!$B$10)*Calculator!$B$9 -> #DIV/0! | AI13: =IF(ISBLANK(AA13),"","RS Means")
AF14: =IFERROR(AA14*AG14,0) -> 0 | AG14: =IF(AA14=0,"",Calculator!$B$5) | AH14: =(AF14/Calculator!$B$10)*Calculator!$B$9 -> #DIV/0! | AI14: =IF(ISBLANK(AA14),"","RS Means")
AF15: =IFERROR(AA15*AG15,0) -> 0 | AG15: =IF(AA15=0,"",Calculator!$B$5) | AH15: =(AF15/Calculator!$B$10)*Calculator!$B$9 -> #DIV/0! | AI15: =IF(ISBLANK(AA15),"","RS Means")
AF16: =IFERROR(AA16*AG16,0) -> 0 | AG16: =IF(AA16=0,"",Calculator!$B$5) | AH16: =(AF16/Calculator!$B$10)*Calculator!$B$9 -> #DIV/0! | AI16: =IF(ISBLANK(AA16),"","RS Means")
AF17: =IFERROR(AA17*AG17,0) -> 0 | AG17: =IF(AA17=0,"",Calculator!$B$5) | AH17: =(AF17/Calculator!$B$10)*Calculator!$B$9 -> #DIV/0! | AI17: =IF(ISBLANK(AA17),"","RS Means")
AF18: =IFERROR(AA18*AG18,0) -> 0 | AG18: =IF(AA18=0,"",Calculator!$B$5) | AH18: =(AF18/Calculator!$B$10)*Calculator!$B$9 -> #DIV/0! | AI18: =IF(ISBLANK(AA18),"","RS Means")
AF19: =IFERROR(AA19*AG19,0) -> 0 | AG19: =IF(AA19=0,"",Calculator!$B$5) | AH19: =(AF19/Calculator!$B$10)*Calculator!$B$9 -> #DIV/0! | AI19: =IF(ISBLANK(AA19),"","RS Means")
AF20: =IFERROR(AA20*AG20,0) -> 0 | AG20: =IF(AA20=0,"",Calculator!$B$5) | AH20: =(AF20/Calculator!$B$10)*Calculator!$B$9 -> #DIV/0! | AI20: =IF(ISBLANK(AA20),"","RS Means")
... AF500: =IFERROR(AA500*AG500,0) -> 0 | AG500: =IF(AA500=0,"",Calculator!$B$5) | AH500: =(AF500/Calculator!$B$10)*Calculator!$B$9 -> #DIV/0! | AI500: =IF(ISBLANK(AA500),"","RS Means")

Sheet 15 yr
AF8: Repro. Cost New | AG8: Less Depreciation | AH8: Total Cost | AI8: Source
AF9: =IFERROR(AA9*AG9,0) -> 0 | AG9: =IF(AA9=0,"",Calculator!$B$6) | AH9: =(AF9/Calculator!$B$10)*Calculator!$B$9 -> #DIV/0! | AI9: =IF(ISBLANK(AA9),"","RS Means")
AF10: =IFERROR(AA10*AG10,0) -> 0 | AG10: =IF(AA10=0,"",Calculator!$B$6) | AH10: =(AF10/Calculator!$B$10)*Calculator!$B$9 -> #DIV/0! | AI10: =IF(ISBLANK(AA10),"","RS Means")
AF11: =IFERROR(AA11*AG11,0) -> 0 | AG11: =IF(AA11=0,"",Calculator!$B$6) | AH11: =(AF11/Calculator!$B$10)*Calculator!$B$9 -> #DIV/0! | AI11: =IF(ISBLANK(AA11),"","RS Means")
AF12: =IFERROR(AA12*AG12,0) -> 0 | AG12: =IF(AA12=0,"",Calculator!$B$6) | AH12: =(AF12/Calculator!$B$10)*Calculator!$B$9 -> #DIV/0! | AI12: =IF(ISBLANK(AA12),"","RS Means")
AF13: =IFERROR(AA13*AG13,0) -> 0 | AG13: =IF(AA13=0,"",Calculator!$B$6) | AH13: =(AF13/Calculator!$B$10)*Calculator!$B$9 -> #DIV/0! | AI13: =IF(ISBLANK(AA13),"","RS Means")
AF14: =IFERROR(AA14*AG14,0) -> 0 | AG14: =IF(AA14=0,"",Calculator!$B$6) | AH14: =(AF14/Calculator!$B$10)*Calculator!$B$9 -> #DIV/0! | AI14: =IF(ISBLANK(AA14),"","RS Means")
AF15: =IFERROR(AA15*AG15,0) -> 0 | AG15: =IF(AA15=0,"",Calculator!$B$6) | AH15: =(AF15/Calculator!$B$10)*Calculator!$B$9 -> #DIV/0! | AI15: =IF(ISBLANK(AA15),"","RS Means")
AF16: =IFERROR(AA16*AG16,0) -> 0 | AG16: =IF(AA16=0,"",Calculator!$B$6) | AH16: =(AF16/Calculator!$B$10)*Calculator!$B$9 -> #DIV/0! | AI16: =IF(ISBLANK(AA16),"","RS Means")
AF17: =IFERROR(AA17*AG17,0) -> 0 | AG17: =IF(AA17=0,"",Calculator!$B$6) | AH17: =(AF17/Calculator!$B$10)*Calculator!$B$9 -> #DIV/0! | AI17: =IF(ISBLANK(AA17),"","RS Means")
AF18: =IFERROR(AA18*AG18,0) -> 0 | AG18: =IF(AA18=0,"",Calculator!$B$6) | AH18: =(AF18/Calculator!$B$10)*Calculator!$B$9 -> #DIV/0! | AI18: =IF(ISBLANK(AA18),"","RS Means")
AF19: =IFERROR(AA19*AG19,0) -> 0 | AG19: =IF(AA19=0,"",Calculator!$B$6) | AH19: =(AF19/Calculator!$B$10)*Calculator!$B$9 -> #DIV/0! | AI19: =IF(ISBLANK(AA19),"","RS Means")
AF20: =IFERROR(AA20*AG20,0) -> 0 | AG20: =IF(AA20=0,"",Calculator!$B$6) | AH20: =(AF20/Calculator!$B$10)*Calculator!$B$9 -> #DIV/0! | AI20: =IF(ISBLANK(AA20),"","RS Means")
... AF500: =IFERROR(AA500*AG500,0) -> 0 | AG500: =IF(AA500=0,"",Calculator!$B$6) | AH500: =(AF500/Calculator!$B$10)*Calculator!$B$9 -> #DIV/0! | AI500: =IF(ISBLANK(AA500),"","RS Means")

Sheet 5 yr
AF8: Repro. Cost New | AG8: Less Depreciation | AH8: Total Cost | AI8: Source
AF9: =IFERROR(AA9*AG9,0) -> 0 | AG9: =IF(AA9=0,"",Calculator!$B$7) | AH9: =(AF9/Calculator!$B$10)*Calculator!$B$9 -> #DIV/0! | AI9: =IF(ISBLANK(AA9),"","RS Means")
AF10: =IFERROR(AA10*AG10,0) -> 0 | AG10: =IF(AA10=0,"",Calculator!$B$7) | AH10: =(AF10/Calculator!$B$10)*Calculator!$B$9 -> #DIV/0! | AI10: =IF(ISBLANK(AA10),"","RS Means")
AF11: =IFERROR(AA11*AG11,0) -> 0 | AG11: =IF(AA11=0,"",Calculator!$B$7) | AH11: =(AF11/Calculator!$B$10)*Calculator!$B$9 -> #DIV/0! | AI11: =IF(ISBLANK(AA11),"","RS Means")
AF12: =IFERROR(AA12*AG12,0) -> 0 | AG12: =IF(AA12=0,"",Calculator!$B$7) | AH12: =(AF12/Calculator!$B$10)*Calculator!$B$9 -> #DIV/0! | AI12: =IF(ISBLANK(AA12),"","RS Means")
AF13: =IFERROR(AA13*AG13,0) -> 0 | AG13: =IF(AA13=0,"",Calculator!$B$7) | AH13: =(AF13/Calculator!$B$10)*Calculator!$B$9 -> #DIV/0! | AI13: =IF(ISBLANK(AA13),"","RS Means")
AF14: =IFERROR(AA14*AG14,0) -> 0 | AG14: =IF(AA14=0,"",Calculator!$B$7) | AH14: =(AF14/Calculator!$B$10)*Calculator!$B$9 -> #DIV/0! | AI14: =IF(ISBLANK(AA14),"","RS Means")
AF15: =IFERROR(AA15*AG15,0) -> 0 | AG15: =IF(AA15=0,"",Calculator!$B$7) | AH15: =(AF15/Calculator!$B$10)*Calculator!$B$9 -> #DIV/0! | AI15: =IF(ISBLANK(AA15),"","RS Means")
AF16: =IFERROR(AA16*AG16,0) -> 0 | AG16: =IF(AA16=0,"",Calculator!$B$7) | AH16: =(AF16/Calculator!$B$10)*Calculator!$B$9 -> #DIV/0! | AI16: =IF(ISBLANK(AA16),"","RS Means")
AF17: =IFERROR(AA17*AG17,0) -> 0 | AG17: =IF(AA17=0,"",Calculator!$B$7) | AH17: =(AF17/Calculator!$B$10)*Calculator!$B$9 -> #DIV/0! | AI17: =IF(ISBLANK(AA17),"","RS Means")
AF18: =IFERROR(AA18*AG18,0) -> 0 | AG18: =IF(AA18=0,"",Calculator!$B$7) | AH18: =(AF18/Calculator!$B$10)*Calculator!$B$9 -> #DIV/0! | AI18: =IF(ISBLANK(AA18),"","RS Means")
AF19: =IFERROR(AA19*AG19,0) -> 0 | AG19: =IF(AA19=0,"",Calculator!$B$7) | AH19: =(AF19/Calculator!$B$10)*Calculator!$B$9 -> #DIV/0! | AI19: =IF(ISBLANK(AA19),"","RS Means")
AF20: =IFERROR(AA20*AG20,0) -> 0 | AG20: =IF(AA20=0,"",Calculator!$B$7) | AH20: =(AF20/Calculator!$B$10)*Calculator!$B$9 -> #DIV/0! | AI20: =IF(ISBLANK(AA20),"","RS Means")
